Workbook

Sheet Raw_Financial
C5: Ticker Symbol | D5: NYSE:CLX
D7: 2026 | E7: 2025 | F7: 2024 | G7: 2023 | H7: 2022
C8: Revenue | D8: 6720 | E8: 7104 | F8: 7093 | G8: 7389 | H8: 7107
C9: Gross Profit | D9: 2844 | E9: 3213 | F9: 3048 | G9: 2908 | H9: 2908
C10: Operating Income | D10: 913 | E10: 1080 | F10: 512 | G10: 408 | H10: 750
C11: Net Income | D11: 587 | E11: 810 | F11: 280 | G11: 149 | H11: 462
C13: Basic EPS | D13: 4.82 | E13: 6.56 | F13: 2.26 | G13: 1.21
C14: Diluted EPS | D14: 4.81 | E14: 6.52 | F14: 2.25 | G14: 1.2
C15: Total Assets | D15: 7794 | E15: 5561 | F15: 1622
C16: Total Equities | D16: 252 | E16: 482 | F16: 492
C18: Operating Cash Flow | D18: 612 | E18: 981 | F18: 695
C19: Capital Expenditures | D19: -207 | E19: -220 | F19: -212
C24: Procter and Gamble
C25: Ticker Symbol | D25: NYSE:PG
D27: 2026 | E27: 2025 | F27: 2024 | G27: 2023 | H27: 2022
C28: Revenue | D28: 87032 | E28: 84284 | F28: 84039 | G28: 82006 | H28: 80187
C29: Gross Profit | D29: 43670 | E29: 43120 | F29: 43191 | G29: 39246 | H29: 38030
C30: Operating Income | D30: 19748 | E30: 20451 | F30: 18545 | G30: 18134 | H30: 17813
C31: Net Income | D31: 16046 | E31: 15974 | F31: 14879 | G31: 14653 | H31: 14742
C33: Total Assets | D33: 126521 | E33: 125231
C34: Total Equity | D34: 54311 | E34: 52284
C35: Basic EPS | D35: 6.75 | E35: 6.67 | F35: 6.18 | G35: 6.07
C36: Diluted EPS | D36: 6.62 | E36: 6.51 | F36: 6.02 | G36: 5.9
C38: Operating Cash Flow | D38: 19556 | E38: 17817 | F38: 19846
C39: Capital Expenditures | D39: -4409 | E39: -3773 | F39: -3322
C43: Colgate-Palmolive
C44: Ticker Symbol | D44: NYSE:CL
D46: (TTM)2026 | E46: 2025 | F46: 2024 | G46: 2023 | H46: 2022
C47: Revenue | D47: 21047 | E47: 20382 | F47: 20101 | G47: 19457 | H47: 17967
C48: Gross Profit | D48: 12450 | E48: 12251 | F48: 12161 | G48: 11326 | H48: 10248
C49: Operating Income | D49: 3130 | E49: 3306 | F49: 4268 | G49: 3984 | H49: 2893
C50: Net Income | D50: 2038 | E50: 2132 | F50: 2889 | G50: 2300 | H50: 1785
C52: Basic EPS | D52: 2.54 | E52: 2.64 | F52: 3.53 | G52: 2.78
C53: Diluted EPS | D53: 2.54 | E53: 2.63 | F53: 3.51 | G53: 2.77
C54: Total Assets | D54: 16790 | E54: 16330 | F54: 16046
C55: Total Equities | D55: 566 | E55: 365 | F55: 544
C57: Operating Cash Flow | D57: 4456 | E57: 4198 | F57: 4107 | G57: 3745
C58: Capital Expenditures | D58: 598 | E58: -564 | F58: -561 | G58: -705
C61: Kimberly-Clark
C62: Ticker Symbol | D62: NASDAQ: KMB
...

Sheet Market Data 
G4: Procter & Gamble | K4: Colgate-Palmolive
C5: Common Valuation Date | D5: 46310 | G5: Common Valuation Date | H5: 46310 | K5: Common Valuation Date | L5: 46310
C6: Closing Share Price | D6: 86.2 | G6: Closing Share Price | H6: 157.08 | K6: Closing Share Price | L6: 92.67
C7: Shares Outstanding | D7: 121775000 | G7: Shares Outstanding | H7: 2378125000 | K7: Shares Outstanding | L7: 799400000
C8: Market Capitalization | D8: =ROUND(D7*D6/1000000,0) -> 10497 | G8: Market Capitalization | H8: =ROUND(H6*H7/1000000,0) -> 373556 | K8: Market Capitalization | L8: =ROUND(L6*L7/1000000,0) -> 74080
C9: Total Debt (mrq) | D9: 5600 | G9: Total Debt (mrq) | H9: 35020 | K9: Total Debt (mrq) | L9: 7860
C10: Cash (mrq) | D10: 143 | G10: Cash (mrq) | H10: 9940 | K10: Cash (mrq) | L10: 1450
C11: EBITDA (TTM) | D11: 1140 | G11: EBITDA (TTM) | H11: 24750 | K11: EBITDA (TTM) | L11: 4980
C15: Kimberly-Clark | G15: Church & Dwight
C16: Common Valuation Date | D16: 46310 | G16: Common Valuation Date | H16: 46310
C17: Closing Share Price | D17: 104.07 | G17: Closing Share Price | H17: 103.08
C18: Shares Outstanding | D18: 331730769 | G18: Shares Outstanding | H18: 236700000
C19: Market Capitalization | D19: =ROUND(D17*D18/1000000,0) -> 34523 | G19: Market Capitalization | H19: =ROUND(H17*H18/1000000,0) -> 24399
C20: Total Debt (mrq) | D20: 6540 | G20: Total Debt (mrq) | H20: 2430
C21: Cash (mrq) | D21: 956 | G21: Cash (mrq) | H21: 254.8
C22: EBITDA (TTM) | D22: 3480 | G22: EBITDA (TTM) | H22: 1350

Sheet Calculations 
C4: PROFITABLITY
C5: Gross Margin | D5: =Raw_Financial!D9/Raw_Financial!D8 -> 0.42321429
C6: Operational Margin | D6: =Raw_Financial!D10/Raw_Financial!D8 -> 0.1358631
C7: Net Margin | D7: =Raw_Financial!D11/Raw_Financial!D8 -> 0.08735119
C8: ROA | D8: =Raw_Financial!D11/Raw_Financial!D15 -> 0.075314344
C9: ROE | D9: =Raw_Financial!D11/Raw_Financial!D16 -> 2.3293651
C11: GROWTH
C12: Revenue CAGR | D12: =(Raw_Financial!D8/Raw_Financial!H8)^(1/4)-1 -> -0.013900498
C13: Operating Income CAGR | D13: =(Raw_Financial!$D$10/Raw_Financial!$H$10)^(1/4)-1 -> 0.050394354
C14: Net Income CAGR | D14: =(Raw_Financial!$D$11/Raw_Financial!$H$11)^(1/4)-1 -> 0.061693189
C15: EPS CAGR (3 years) | D15: =(Raw_Financial!D14/Raw_Financial!G14)^(1/3)-1 -> 0.58850265
C17: FINANCIAL HEALTH
C18: Debt-to-Equity | D18: ='Market Data '!D9/Raw_Financial!D16 -> 22.222222
C19: Cash-to-Debt | D19: ='Market Data '!D10/'Market Data '!D9 -> 0.025535714
C21: VALUATION
C22: P/E | D22: ='Market Data '!D6/Raw_Financial!D14 -> 17.920998
C23: P/B | D23: ='Market Data '!D8/Raw_Financial!D16 -> 41.654762
C24: EV | D24: ='Market Data '!D8+'Market Data '!D9-'Market Data '!D10 -> 15954
C25: EV/EBITDA | D25: =D24/'Market Data '!D11 -> 13.994737
C29: Procter & Gamble
C30: PROFITABLITY
C31: Gross Margin | D31: =Raw_Financial!D29/Raw_Financial!D28 -> 0.50176946
C32: Operational Margin | D32: =Raw_Financial!D30/Raw_Financial!D28 -> 0.22690505
C33: Net Margin | D33: =Raw_Financial!D31/Raw_Financial!D28 -> 0.18436897
C34: ROA | D34: =Raw_Financial!D31/Raw_Financial!D33 -> 0.1268248
C35: ROE | D35: =Raw_Financial!D31/Raw_Financial!D34 -> 0.29544659
C37: GROWTH
C38: Revenue CAGR | D38: =(Raw_Financial!D28/Raw_Financial!H28)^(1/4)-1 -> 0.020689741
C39: Operating Income CAGR | D39: =(Raw_Financial!$D$30/Raw_Financial!$H$30)^(1/4)-1 -> 0.026116126
C40: Net Income CAGR | D40: =(Raw_Financial!$D$31/Raw_Financial!$H$31)^(1/4)-1 -> 0.021415856
C41: EPS CAGR (3 years) | D41: =(Raw_Financial!D36/Raw_Financial!G36)^(1/3)-1 -> 0.039127071
C43: FINANCIAL HEALTH
C44: Debt-to-Equity | D44: ='Market Data '!H9/Raw_Financial!D34 -> 0.64480492
C45: Cash-to-Debt | D45: ='Market Data '!H10/'Market Data '!H9 -> 0.28383781
C47: VALUATION
C48: P/E | D48: ='Market Data '!H6/Raw_Financial!D36 -> 23.728097
C49: P/B | D49: ='Market Data '!H8/Raw_Financial!D34 -> 6.878091
C50: EV | D50: ='Market Data '!H8+'Market Data '!H9-'Market Data '!H10 -> 398636
C51: EV/EBITDA | D51: =D50/'Market Data '!H11 -> 16.106505
C55: Colgate-Palmolive
...

Sheet Peer Comparison
F4: PEERS | J4: Relative Difference
C6: Price-to-Earnings | D6: =+'Calculations '!D22 -> 17.920998 | G6: =MEDIAN('Calculations '!D48,'Calculations '!D74,'Calculations '!D100,'Calculations '!D126) -> 28.383279 | J6: =IFERROR((D6-G6)/G6,"N/M") -> -0.36860721
C7: Price to Book | D7: =+'Calculations '!D23 -> 41.654762 | G7: =MEDIAN('Calculations '!D49,'Calculations '!D75,'Calculations '!D101,'Calculations '!D127) -> 12.650091 | J7: =IFERROR((D7-G7)/G7,"N/M") -> 2.2928428
C8: EV/EBITDA | D8: =+'Calculations '!D25 -> 13.994737 | G8: =MEDIAN('Calculations '!D129,'Calculations '!D103,'Calculations '!D77,'Calculations '!D51) -> 16.134578 | J8: =IFERROR((D8-G8)/G8,"N/M") -> -0.13262454
C10: Operating Margin | D10: =+'Calculations '!D6 -> 0.1358631 | G10: =MEDIAN('Calculations '!D32,'Calculations '!D58,'Calculations '!D84,'Calculations '!D110) -> 0.16314627 | J10: {=IFERROR((D10-G10)/G10,N/M)} -> -0.16723139
C11: Net Margin | D11: =+'Calculations '!D7 -> 0.08735119 | G11: =MEDIAN('Calculations '!D111,'Calculations '!D85,'Calculations '!D59,'Calculations '!D33) -> 0.11874049 | J11: {=IFERROR((D11-G11)/G11,N/M)} -> -0.26435212
C12: ROE | D12: =+'Calculations '!D9 -> 2.3293651 | G12: =MEDIAN('Calculations '!D35,'Calculations '!D61,'Calculations '!D87,'Calculations '!D113) -> 0.66933482 | J12: {=IFERROR((D12-G12)/G12,N/M)} -> 2.4801194
C13: ROA | D13: =+'Calculations '!D8 -> 0.075314344 | G13: =MEDIAN('Calculations '!D112,'Calculations '!D86,'Calculations '!D60,'Calculations '!D34) -> 0.11337494 | J13: {=IFERROR((D13-G13)/G13,N/M)} -> -0.33570557
C15: Revenue CAGR | D15: ='Calculations '!D12 -> -0.013900498 | G15: =MEDIAN('Calculations '!D38,'Calculations '!D64,'Calculations '!D90,'Calculations '!D116) -> 0.029108588 | J15: =IFERROR((D15-G15)/G15,"N/M") -> -1.4775394
C16: Operating Income CAGR | D16: ='Calculations '!D13 -> 0.050394354 | G16: =MEDIAN('Calculations '!D39,'Calculations '!D65,'Calculations '!D91,'Calculations '!D117) -> 0.030016529 | J16: =IFERROR((D16-G16)/G16,"N/M") -> 0.67888676
C17: Net Income CAGR | D17: ='Calculations '!D14 -> 0.061693189 | G17: =MEDIAN('Calculations '!D118,'Calculations '!D92,'Calculations '!D66,'Calculations '!D40) -> 0.027554326 | J17: =IFERROR((D17-G17)/G17,"N/M") -> 1.2389656
C18: EPS CARG (3 Years) | D18: ='Calculations '!D15 -> 0.58850265 | G18: =MEDIAN('Calculations '!D41,'Calculations '!D67,'Calculations '!D93,'Calculations '!D119) -> 0.023359777 | J18: =IFERROR((D18-G18)/G18,"N/M") -> 24.192991
C20: Debt-to-Equity | D20: ='Calculations '!D18 -> 22.222222 | G20: =MEDIAN('Calculations '!D44,'Calculations '!D70,'Calculations '!D96,'Calculations '!D122) -> 2.0673331 | J20: =IFERROR((D20-G20)/G20,"N/M") -> 9.7492219
C21: Cash-to-Debt | D21: ='Calculations '!D19 -> 0.025535714 | G21: =MEDIAN('Calculations '!D123,'Calculations '!D97,'Calculations '!D71,'Calculations '!D45) -> 0.16532787 | J21: =IFERROR((D21-G21)/G21,"N/M") -> -0.84554501

Sheet Sources
C2: References:
C4: Clorox 2026 Annual Report
C5: https://s204.q4cdn.com/178752512/files/doc_financials/2026/ar/The-Clorox-Company-FY26-Integrated-Annual-Report.pdf
C6: Clorox 2023 Annual Report
C7: Clorox 2023 Integrated Annual Report
C8: Clorox Shares Outstanding & Market Capitalization
C9: https://companiesmarketcap.com/clorox/shares-outstanding/
C10: Clorox Share Price, Debt, Cash, and EBITDA (October 15, 2026)
C11: https://finance.yahoo.com/quote/CLX/key-statistics/
C12: Clorox Cyberattack (August 2023) leading to IT overhaul and cost drag
C13: https://www.reuters.com/business/retail-consumer/clorox-expects-quarterly-loss-hit-cyberattack-2023-10-04/
C14: https://www.cybersecuritydive.com/news/clorox-warns-shortages-cyberattack/694030/
... C64: https://finance.yahoo.com/quote/CHD/key-statistics/

Sheet Tidy Calculations
A1: Companies | B1: Price-to-Earnings | C1: Price to Book | D1: EV/EBITDA | E1: Operating Margin | F1: Net Margin | G1: ROA | H1: ROE | I1: Revenue CAGR | J1: Operating Income CAGR | K1: Net Income CAGR | L1: EPS CARG (3 Years) | M1: Debt-to-Equity | N1: Cash-to-Debt
A2: Clorox | B2: 17.920998 | C2: 41.654762 | D2: 13.994737 | E2: 0.1358631 | F2: 0.08735119 | G2: 0.075314344 | H2: 2.3293651 | I2: -0.013900498 | J2: 0.050394354 | K2: 0.061693189 | L2: 0.58850265 | M2: 22.222222 | N2: 0.025535714
A3: Procter & Gamble | B3: 23.728097 | C3: 6.878091 | D3: 16.106505 | E3: 0.22690505 | F3: 0.18436897 | G3: 0.1268248 | H3: 0.29544659 | I3: 0.020689741 | J3: 0.026116126 | K3: 0.021415856 | L3: 0.039127071 | M3: 0.64480492 | N3: 0.28383781
A4: Colgate-Palmolive | B4: 36.484252 | C4: 130.88339 | D4: 16.162651 | E4: 0.14871478 | F4: 0.096830902 | G4: 0.12138177 | H4: 3.6007067 | I4: 0.040348052 | J4: 0.019879767 | K4: 0.033692796 | L4: -0.028480961 | M4: 4.1942369 | N4: 0.18447837
A5: Kimberly-Clark | B5: 17.729131 | C5: 18.422092 | D5: 11.525 | E5: 0.15162847 | F5: 0.11791315 | G5: 0.10536811 | H5: 1.0432231 | I5: 0.0027326807 | J5: 0.033916933 | K5: 0.0027035972 | L5: 0.040559198 | M5: 3.4898613 | N5: 0.14617737
A6: Church & Dwight | B6: 33.038462 | C6: 5.6118037 | D6: 19.684593 | E6: 0.17466408 | F6: 0.11956783 | G6: 0.08179492 | H6: 0.17130503 | I6: 0.037527435 | J6: 0.16149741 | K6: 0.15820667 | L6: 0.0075924816 | M6: 0.55890335 | N6: 0.10485597
A7: Peer Median | B7: =MEDIAN(B3:B6) -> 28.383279 | C7: =MEDIAN(C3:C6) -> 12.650091 | D7: =MEDIAN(D3:D6) -> 16.134578 | E7: =MEDIAN(E3:E6) -> 0.16314627 | F7: =MEDIAN(F3:F6) -> 0.11874049 | G7: =MEDIAN(G3:G6) -> 0.11337494 | H7: =MEDIAN(H3:H6) -> 0.66933482 | I7: =MEDIAN(I3:I6) -> 0.029108588 | ... N7: =MEDIAN(N3:N6) -> 0.16532787

Sheet Tidy Market Data
A1: Companies | B1: Closing Share Price | C1: Shares Outstanding | D1: Market Capitalization | E1: Total Debt (mrq) | F1: Cash (mrq) | G1: EBITDA (TTM)
A2: Clorox | B2: 86.2 | C2: 121775000 | D2: =ROUND(C2*B2/1000000,0) -> 10497 | E2: 5600 | F2: 143 | G2: 1140
A3: Procter & Gamble | B3: 157.08 | C3: 2378125000 | D3: =ROUND(B3*C3/1000000,0) -> 373556 | E3: 35020 | F3: 9940 | G3: 24750
A4: Colgate-Palmolive | B4: 92.67 | C4: 799400000 | D4: =ROUND(B4*C4/1000000,0) -> 74080 | E4: 7860 | F4: 1450 | G4: 4980
A5: Kimberly-Clark | B5: 104.07 | C5: 331730769 | D5: =ROUND(B5*C5/1000000,0) -> 34523 | E5: 6540 | F5: 956 | G5: 3480
A6: Church & Dwight | B6: 103.08 | C6: 236700000 | D6: =ROUND(B6*C6/1000000,0) -> 24399 | E6: 2430 | F6: 254.8 | G6: 1350
A7: Peer Median | B7: =MEDIAN(B3:B6) -> 103.575 | C7: =MEDIAN(C3:C6) -> 5.6556538e+08 | D7: =MEDIAN(D3:D6) -> 54301.5 | E7: =MEDIAN(E3:E6) -> 7200 | F7: =MEDIAN(F3:F6) -> 1203 | G7: =MEDIAN(G3:G6) -> 4230
